{
  "timestamp": 1752303822.0937288,
  "summary": {
    "total_test_suites": 3,
    "passed_suites": 3,
    "failed_suites": 0
  },
  "detailed_results": {
    "lightweight": {
      "exit_code": 0,
      "success": true,
      "stdout": "\ud83e\uddea LIGHTWEIGHT TEST SUITE\n========================================\n\n\ud83d\udcc1 Testing file structure...\n   \u2705 All 5 critical files present\n\ud83d\udd0d Testing imports...\n   \u2705 GitHub Codex bridge import successful\n   \u2705 MCP bridge import successful\n   \u2705 Bridge manager import successful\n\n\u2699\ufe0f  Testing basic functionality...\n   \u2705 GitHub bridge health check passed\n   \u2705 GitHub bridge code generation passed\n   \u2705 MCP bridge health check passed\n\n\ud83c\udfbc Testing orchestrator...\n   \u2705 Orchestrator collaboration test passed\n\n\ud83d\udcca LIGHTWEIGHT TEST SUMMARY\n==============================\n   Tests Passed: 4/4\n   Success Rate: 100.0%\n   Duration: 1.12s\n\n\u2705 ALL LIGHTWEIGHT TESTS PASSED!\n\ud83c\udf89 System is ready for full testing\n",
      "stderr": "INFO:refactored_orchestrator:Initialized 4 AI providers\nINFO:refactored_orchestrator:Started collaboration session lightweight_test with 2 agents\nINFO:refactored_orchestrator:Anthropic Claude generated response in 0.10s\nINFO:refactored_orchestrator:Google Gemini generated response in 0.10s\nINFO:refactored_orchestrator:Anthropic Claude generated response in 0.10s\nINFO:refactored_orchestrator:Google Gemini generated response in 0.10s\nINFO:refactored_orchestrator:Anthropic Claude generated response in 0.10s\nINFO:refactored_orchestrator:Google Gemini generated response in 0.10s\nINFO:refactored_orchestrator:Completed collaboration lightweight_test in 0.61s\nException ignored in: <function BaseSubprocessTransport.__del__ at 0x777ad042ede0>\nTraceback (most recent call last):\n  File \"/usr/lib/python3.12/asyncio/base_subprocess.py\", line 126, in __del__\n  File \"/usr/lib/python3.12/asyncio/base_subprocess.py\", line 104, in close\n  File \"/usr/lib/python3.12/asyncio/unix_events.py\", line 767, in close\n  File \"/usr/lib/python3.12/asyncio/unix_events.py\", line 753, in write_eof\n  File \"/usr/lib/python3.12/asyncio/base_events.py\", line 795, in call_soon\n  File \"/usr/lib/python3.12/asyncio/base_events.py\", line 541, in _check_closed\nRuntimeError: Event loop is closed\nException ignored in: <function BaseSubprocessTransport.__del__ at 0x777ad042ede0>\nTraceback (most recent call last):\n  File \"/usr/lib/python3.12/asyncio/base_subprocess.py\", line 126, in __del__\n  File \"/usr/lib/python3.12/asyncio/base_subprocess.py\", line 104, in close\n  File \"/usr/lib/python3.12/asyncio/unix_events.py\", line 767, in close\n  File \"/usr/lib/python3.12/asyncio/unix_events.py\", line 753, in write_eof\n  File \"/usr/lib/python3.12/asyncio/base_events.py\", line 795, in call_soon\n  File \"/usr/lib/python3.12/asyncio/base_events.py\", line 541, in _check_closed\nRuntimeError: Event loop is closed\nException ignored in: <function BaseSubprocessTransport.__del__ at 0x777ad042ede0>\nTraceback (most recent call last):\n  File \"/usr/lib/python3.12/asyncio/base_subprocess.py\", line 126, in __del__\n  File \"/usr/lib/python3.12/asyncio/base_subprocess.py\", line 104, in close\n  File \"/usr/lib/python3.12/asyncio/unix_events.py\", line 767, in close\n  File \"/usr/lib/python3.12/asyncio/unix_events.py\", line 753, in write_eof\n  File \"/usr/lib/python3.12/asyncio/base_events.py\", line 795, in call_soon\n  File \"/usr/lib/python3.12/asyncio/base_events.py\", line 541, in _check_closed\nRuntimeError: Event loop is closed\nException ignored in: <function BaseSubprocessTransport.__del__ at 0x777ad042ede0>\nTraceback (most recent call last):\n  File \"/usr/lib/python3.12/asyncio/base_subprocess.py\", line 126, in __del__\n  File \"/usr/lib/python3.12/asyncio/base_subprocess.py\", line 104, in close\n  File \"/usr/lib/python3.12/asyncio/unix_events.py\", line 767, in close\n  File \"/usr/lib/python3.12/asyncio/unix_events.py\", line 753, in write_eof\n  File \"/usr/lib/python3.12/asyncio/base_events.py\", line 795, in call_soon\n  File \"/usr/lib/python3.12/asyncio/base_events.py\", line 541, in _check_closed\nRuntimeError: Event loop is closed\nException ignored in: <function BaseSubprocessTransport.__del__ at 0x777ad042ede0>\nTraceback (most recent call last):\n  File \"/usr/lib/python3.12/asyncio/base_subprocess.py\", line 126, in __del__\n  File \"/usr/lib/python3.12/asyncio/base_subprocess.py\", line 104, in close\n  File \"/usr/lib/python3.12/asyncio/unix_events.py\", line 767, in close\n  File \"/usr/lib/python3.12/asyncio/unix_events.py\", line 753, in write_eof\n  File \"/usr/lib/python3.12/asyncio/base_events.py\", line 795, in call_soon\n  File \"/usr/lib/python3.12/asyncio/base_events.py\", line 541, in _check_closed\nRuntimeError: Event loop is closed\n"
    },
    "orchestrator": {
      "exit_code": 0,
      "success": true,
      "stdout": "Testing Enhanced SDLC Orchestrator\n==================================================\n\nTesting orchestra paradigm...\nResult: completed\nSynthesis quality: high\n\nTesting mesh paradigm...\nResult: completed\n\nTesting swarm paradigm...\nResult: completed\n\nTesting weaver paradigm...\nResult: completed\n\nTesting ecosystem paradigm...\nResult: completed\n\nPerformance Report:\nTotal sessions: 0\nActive sessions: 5\n",
      "stderr": "INFO:__main__:Initialized 4 AI providers\nINFO:__main__:Started collaboration session test_orchestra with 2 agents\nINFO:__main__:Google Gemini generated response in 0.10s\nINFO:__main__:Anthropic Claude generated response in 0.10s\nINFO:__main__:Completed collaboration test_orchestra in 0.10s\nINFO:__main__:Started collaboration session test_mesh with 2 agents\nINFO:__main__:Google Gemini generated response in 0.10s\nINFO:__main__:Anthropic Claude generated response in 0.10s\nINFO:__main__:Google Gemini generated response in 0.10s\nINFO:__main__:Anthropic Claude generated response in 0.10s\nINFO:__main__:Google Gemini generated response in 0.10s\nINFO:__main__:Anthropic Claude generated response in 0.10s\nINFO:__main__:Completed collaboration test_mesh in 0.61s\nINFO:__main__:Started collaboration session test_swarm with 2 agents\nINFO:__main__:Google Gemini generated response in 0.10s\nINFO:__main__:Anthropic Claude generated response in 0.10s\nINFO:__main__:Completed collaboration test_swarm in 0.10s\nINFO:__main__:Started collaboration session test_weaver with 2 agents\nINFO:__main__:Google Gemini generated response in 0.10s\nINFO:__main__:Anthropic Claude generated response in 0.10s\nINFO:__main__:Completed collaboration test_weaver in 0.10s\nINFO:__main__:Started collaboration session test_ecosystem with 2 agents\nINFO:__main__:Google Gemini generated response in 0.10s\nINFO:__main__:Anthropic Claude generated response in 0.10s\nINFO:__main__:Google Gemini generated response in 0.10s\nINFO:__main__:Anthropic Claude generated response in 0.10s\nINFO:__main__:Google Gemini generated response in 0.10s\nINFO:__main__:Anthropic Claude generated response in 0.10s\nINFO:__main__:Completed collaboration test_ecosystem in 0.61s\n"
    },
    "full_suite": {
      "exit_code": 0,
      "success": true,
      "stdout": "\ud83e\uddea STARTING COMPREHENSIVE END-TO-END TEST SUITE\n======================================================================\n\n\ud83d\udcc1 INFRASTRUCTURE TESTS\n   \u2705 PASS File Structure Check (0.028s)\n   \u2705 PASS Python Imports (0.960s)\n   \u2705 PASS CSS Syntax Validation (0.017s)\n   \u2705 PASS TSX Syntax Validation (0.025s)\n\n\ud83d\udd27 MCP BRIDGE TESTS\n   \u2705 PASS MCP Bridge Initialization (0.001s)\n   \u2705 PASS MCP Bridge Health Check (0.267s)\n   \u2705 PASS MCP Server Communication (0.090s)\n\n\ud83c\udf09 BRIDGE MANAGER TESTS\n   \u2705 PASS Bridge Manager Initialization (0.000s)\n   \u2705 PASS Bridge Manager Health Check (4.448s)\n   \u2705 PASS Bridge Manager Task Routing (0.001s)\n\n\ud83e\udd16 A2A COORDINATOR TESTS\n   \u2705 PASS A2A Coordinator Initialization (0.119s)\n   \u2705 PASS A2A Message Creation (0.000s)\n   \u2705 PASS A2A Message Routing (0.149s)\n\n\ud83c\udfbc ORCHESTRATOR TESTS\n   \u2705 PASS Orchestrator Initialization (0.000s)\n   \u2705 PASS Orchestrator Collaboration (0.631s)\n\n\ud83d\udd17 INTEGRATION TESTS\n   \u2705 PASS Full Workflow Integration (0.329s)\n\n\u26a1 PERFORMANCE TESTS\n   \u2705 PASS Response Times (0.100s)\n   \u2705 PASS Concurrent Operations (0.540s)\n\n\ud83c\udfaf TEST SUMMARY\n==================================================\n   Total Tests: 18\n   Passed: 18 \u2705\n   Failed: 0 \u274c\n   Success Rate: 100.0%\n   Total Duration: 7.71s\n\n\u2705 ALL TESTS PASSED\n\n\ud83d\udcc4 Detailed report saved to: test_report_20250712_020341.json\n",
      "stderr": "2025-07-12 02:03:34,109 - src.services.bridges.mcp_bridge - INFO - MCP Bridge database initialized\n2025-07-12 02:03:34,110 - src.services.bridges.mcp_bridge - INFO - Registered MCP server: perplexity\n2025-07-12 02:03:34,110 - src.services.bridges.mcp_bridge - INFO - Registered MCP server: notion\n2025-07-12 02:03:34,110 - src.services.bridges.mcp_bridge - INFO - Registered MCP server: eslint\n2025-07-12 02:03:34,111 - src.services.bridges.mcp_bridge - INFO - Registered MCP server: deepseek\n2025-07-12 02:03:34,111 - src.services.bridges.mcp_bridge - INFO - Registered MCP server: jenkins\n2025-07-12 02:03:34,956 - src.services.bridges.mcp_bridge - INFO - Started MCP server: perplexity\n2025-07-12 02:03:34,996 - src.services.bridges.mcp_bridge - INFO - Started MCP server: notion\n2025-07-12 02:03:35,059 - src.services.bridges.mcp_bridge - INFO - Started MCP server: eslint\n2025-07-12 02:03:35,113 - src.services.bridges.mcp_bridge - INFO - Started MCP server: deepseek\n2025-07-12 02:03:35,175 - src.services.bridges.mcp_bridge - INFO - Started MCP server: jenkins\n2025-07-12 02:03:39,297 - src.services.bridges.blackbox_ai_bridge - ERROR - Blackbox.ai authentication error: 'MockSession' object does not support the asynchronous context manager protocol\n2025-07-12 02:03:39,314 - src.services.bridges.mcp_bridge - INFO - Started MCP server: perplexity\n2025-07-12 02:03:39,380 - src.services.bridges.mcp_bridge - INFO - Started MCP server: notion\n2025-07-12 02:03:39,543 - src.services.bridges.mcp_bridge - INFO - Started MCP server: eslint\n2025-07-12 02:03:39,620 - src.services.bridges.mcp_bridge - INFO - Started MCP server: deepseek\n2025-07-12 02:03:39,711 - src.services.bridges.mcp_bridge - INFO - Started MCP server: jenkins\n2025-07-12 02:03:39,847 - refactored_orchestrator - INFO - Initialized 4 AI providers\n2025-07-12 02:03:39,879 - a2a_mcp_coordinator - INFO - Initialized 6 A2A agents for MCP coordination\n2025-07-12 02:03:39,880 - a2a_mcp_coordinator - INFO - Created A2A message: test_client -> research_agent [research_documentation]\n2025-07-12 02:03:39,880 - a2a_mcp_coordinator - INFO - Created A2A message: test_client -> research_agent [research_documentation]\n2025-07-12 02:03:39,943 - a2a_mcp_coordinator - INFO - Created A2A message: test_client -> mcp_server [research_docs]\n2025-07-12 02:03:40,029 - refactored_orchestrator - INFO - Started collaboration session test_session with 2 agents\n2025-07-12 02:03:40,134 - refactored_orchestrator - INFO - Anthropic Claude generated response in 0.10s\n2025-07-12 02:03:40,243 - refactored_orchestrator - INFO - Google Gemini generated response in 0.11s\n2025-07-12 02:03:40,350 - refactored_orchestrator - INFO - Anthropic Claude generated response in 0.11s\n2025-07-12 02:03:40,453 - refactored_orchestrator - INFO - Google Gemini generated response in 0.10s\n2025-07-12 02:03:40,556 - refactored_orchestrator - INFO - Anthropic Claude generated response in 0.10s\n2025-07-12 02:03:40,659 - refactored_orchestrator - INFO - Google Gemini generated response in 0.10s\n2025-07-12 02:03:40,660 - refactored_orchestrator - INFO - Completed collaboration test_session in 0.63s\n2025-07-12 02:03:40,660 - a2a_mcp_coordinator - INFO - Created A2A message: coordinator -> research_agent [research_documentation]\n2025-07-12 02:03:40,726 - a2a_mcp_coordinator - INFO - Created A2A message: coordinator -> api_scout [discover_apis]\n2025-07-12 02:03:40,805 - a2a_mcp_coordinator - INFO - Created A2A message: coordinator -> orchestrator [generate_project]\n2025-07-12 02:03:40,806 - refactored_orchestrator - ERROR - Collaboration a2a_1752303820805_5 failed: Invalid agents: ['qwen']\n2025-07-12 02:03:40,806 - a2a_mcp_coordinator - INFO - Created A2A message: coordinator -> knowledge_keeper [store_knowledge]\n2025-07-12 02:03:40,990 - a2a_mcp_coordinator - INFO - Created A2A message: perf_test -> research_agent [research_documentation]\n2025-07-12 02:03:41,090 - a2a_mcp_coordinator - INFO - Created A2A message: concurrent_test_0 -> research_agent [research_documentation]\n2025-07-12 02:03:41,090 - a2a_mcp_coordinator - INFO - Created A2A message: concurrent_test_1 -> research_agent [research_documentation]\n2025-07-12 02:03:41,090 - a2a_mcp_coordinator - INFO - Created A2A message: concurrent_test_2 -> research_agent [research_documentation]\n2025-07-12 02:03:41,090 - a2a_mcp_coordinator - INFO - Created A2A message: concurrent_test_3 -> research_agent [research_documentation]\n2025-07-12 02:03:41,090 - a2a_mcp_coordinator - INFO - Created A2A message: concurrent_test_4 -> research_agent [research_documentation]\nException ignored in: <function BaseSubprocessTransport.__del__ at 0x78bf0dd531a0>\nTraceback (most recent call last):\n  File \"/usr/lib/python3.12/asyncio/base_subprocess.py\", line 126, in __del__\n    self.close()\n  File \"/usr/lib/python3.12/asyncio/base_subprocess.py\", line 104, in close\n    proto.pipe.close()\n  File \"/usr/lib/python3.12/asyncio/unix_events.py\", line 767, in close\n    self.write_eof()\n  File \"/usr/lib/python3.12/asyncio/unix_events.py\", line 753, in write_eof\n    self._loop.call_soon(self._call_connection_lost, None)\n  File \"/usr/lib/python3.12/asyncio/base_events.py\", line 795, in call_soon\n    self._check_closed()\n  File \"/usr/lib/python3.12/asyncio/base_events.py\", line 541, in _check_closed\n    raise RuntimeError('Event loop is closed')\nRuntimeError: Event loop is closed\nException ignored in: <function BaseSubprocessTransport.__del__ at 0x78bf0dd531a0>\nTraceback (most recent call last):\n  File \"/usr/lib/python3.12/asyncio/base_subprocess.py\", line 126, in __del__\n    self.close()\n  File \"/usr/lib/python3.12/asyncio/base_subprocess.py\", line 104, in close\n    proto.pipe.close()\n  File \"/usr/lib/python3.12/asyncio/unix_events.py\", line 767, in close\n    self.write_eof()\n  File \"/usr/lib/python3.12/asyncio/unix_events.py\", line 753, in write_eof\n    self._loop.call_soon(self._call_connection_lost, None)\n  File \"/usr/lib/python3.12/asyncio/base_events.py\", line 795, in call_soon\n    self._check_closed()\n  File \"/usr/lib/python3.12/asyncio/base_events.py\", line 541, in _check_closed\n    raise RuntimeError('Event loop is closed')\nRuntimeError: Event loop is closed\nException ignored in: <function BaseSubprocessTransport.__del__ at 0x78bf0dd531a0>\nTraceback (most recent call last):\n  File \"/usr/lib/python3.12/asyncio/base_subprocess.py\", line 126, in __del__\n    self.close()\n  File \"/usr/lib/python3.12/asyncio/base_subprocess.py\", line 104, in close\n    proto.pipe.close()\n  File \"/usr/lib/python3.12/asyncio/unix_events.py\", line 767, in close\n    self.write_eof()\n  File \"/usr/lib/python3.12/asyncio/unix_events.py\", line 753, in write_eof\n    self._loop.call_soon(self._call_connection_lost, None)\n  File \"/usr/lib/python3.12/asyncio/base_events.py\", line 795, in call_soon\n    self._check_closed()\n  File \"/usr/lib/python3.12/asyncio/base_events.py\", line 541, in _check_closed\n    raise RuntimeError('Event loop is closed')\nRuntimeError: Event loop is closed\nException ignored in: <function BaseSubprocessTransport.__del__ at 0x78bf0dd531a0>\nTraceback (most recent call last):\n  File \"/usr/lib/python3.12/asyncio/base_subprocess.py\", line 126, in __del__\n    self.close()\n  File \"/usr/lib/python3.12/asyncio/base_subprocess.py\", line 104, in close\n    proto.pipe.close()\n  File \"/usr/lib/python3.12/asyncio/unix_events.py\", line 767, in close\n    self.write_eof()\n  File \"/usr/lib/python3.12/asyncio/unix_events.py\", line 753, in write_eof\n    self._loop.call_soon(self._call_connection_lost, None)\n  File \"/usr/lib/python3.12/asyncio/base_events.py\", line 795, in call_soon\n    self._check_closed()\n  File \"/usr/lib/python3.12/asyncio/base_events.py\", line 541, in _check_closed\n    raise RuntimeError('Event loop is closed')\nRuntimeError: Event loop is closed\nException ignored in: <function BaseSubprocessTransport.__del__ at 0x78bf0dd531a0>\nTraceback (most recent call last):\n  File \"/usr/lib/python3.12/asyncio/base_subprocess.py\", line 126, in __del__\n  File \"/usr/lib/python3.12/asyncio/base_subprocess.py\", line 104, in close\n  File \"/usr/lib/python3.12/asyncio/unix_events.py\", line 767, in close\n  File \"/usr/lib/python3.12/asyncio/unix_events.py\", line 753, in write_eof\n  File \"/usr/lib/python3.12/asyncio/base_events.py\", line 795, in call_soon\n  File \"/usr/lib/python3.12/asyncio/base_events.py\", line 541, in _check_closed\nRuntimeError: Event loop is closed\nException ignored in: <function BaseSubprocessTransport.__del__ at 0x78bf0dd531a0>\nTraceback (most recent call last):\n  File \"/usr/lib/python3.12/asyncio/base_subprocess.py\", line 126, in __del__\n  File \"/usr/lib/python3.12/asyncio/base_subprocess.py\", line 104, in close\n  File \"/usr/lib/python3.12/asyncio/unix_events.py\", line 767, in close\n  File \"/usr/lib/python3.12/asyncio/unix_events.py\", line 753, in write_eof\n  File \"/usr/lib/python3.12/asyncio/base_events.py\", line 795, in call_soon\n  File \"/usr/lib/python3.12/asyncio/base_events.py\", line 541, in _check_closed\nRuntimeError: Event loop is closed\nException ignored in: <function BaseSubprocessTransport.__del__ at 0x78bf0dd531a0>\nTraceback (most recent call last):\n  File \"/usr/lib/python3.12/asyncio/base_subprocess.py\", line 126, in __del__\n  File \"/usr/lib/python3.12/asyncio/base_subprocess.py\", line 104, in close\n  File \"/usr/lib/python3.12/asyncio/unix_events.py\", line 767, in close\n  File \"/usr/lib/python3.12/asyncio/unix_events.py\", line 753, in write_eof\n  File \"/usr/lib/python3.12/asyncio/base_events.py\", line 795, in call_soon\n  File \"/usr/lib/python3.12/asyncio/base_events.py\", line 541, in _check_closed\nRuntimeError: Event loop is closed\nException ignored in: <function BaseSubprocessTransport.__del__ at 0x78bf0dd531a0>\nTraceback (most recent call last):\n  File \"/usr/lib/python3.12/asyncio/base_subprocess.py\", line 126, in __del__\n  File \"/usr/lib/python3.12/asyncio/base_subprocess.py\", line 104, in close\n  File \"/usr/lib/python3.12/asyncio/unix_events.py\", line 767, in close\n  File \"/usr/lib/python3.12/asyncio/unix_events.py\", line 753, in write_eof\n  File \"/usr/lib/python3.12/asyncio/base_events.py\", line 795, in call_soon\n  File \"/usr/lib/python3.12/asyncio/base_events.py\", line 541, in _check_closed\nRuntimeError: Event loop is closed\nException ignored in: <function BaseSubprocessTransport.__del__ at 0x78bf0dd531a0>\nTraceback (most recent call last):\n  File \"/usr/lib/python3.12/asyncio/base_subprocess.py\", line 126, in __del__\n  File \"/usr/lib/python3.12/asyncio/base_subprocess.py\", line 104, in close\n  File \"/usr/lib/python3.12/asyncio/unix_events.py\", line 767, in close\n  File \"/usr/lib/python3.12/asyncio/unix_events.py\", line 753, in write_eof\n  File \"/usr/lib/python3.12/asyncio/base_events.py\", line 795, in call_soon\n  File \"/usr/lib/python3.12/asyncio/base_events.py\", line 541, in _check_closed\nRuntimeError: Event loop is closed\n"
    }
  }
}